Workbook

Sheet README
A1: UGC DEB Approved Online Programmes — AY 2025-26 (Jan-Feb 2026 Session)
A2: Source: UGC notice dated 08-Jan-2026 | https://deb.ugc.ac.in
A4: PURPOSE
A5: This workbook is the master verification register for online programmes under UGC-DEB.
A6: It lets you check at a glance whether a university and its specific programme are UGC-DEB approved
A7: for online delivery, plus placeholder columns for AICTE / NAAC / NIRF data to be filled in later.
A9: SHEETS
A10: 1. Master_Online — every approved online programme as one row (filterable by state, type, programme).
A11: 2. University_Summary — one row per university with programme count and approval columns.
A12: 3. Verification_Lookup — paste a university name; formulas confirm UGC-DEB status and program count.
A13: 4. Stats — high-level counts by state, type, and programme category.
A15: COLOR / FLAG LEGEND
... A283: whether the rank actually applies to the programme they're researching.

Sheet Master_Online
A1: S.No | B1: UGC S.No | C1: State | D1: HEI Type | E1: University Name | F1: Programme Name | G1: Programme Category | H1: Level | I1: Mode | J1: UGC-DEB Approved | K1: UGC Notice | L1: Recognition Period | M1: Recognition End Date | N1: Validity Status | O1: AICTE Approved | P1: NAAC Grade | Q1: NAAC CGPA | R1: NAAC Cycle | S1: NAAC Declared On | T1: NAAC Validity Status | U1: NAAC Tier | V1: AACSB Status | W1: AACSB Accredited School | X1: AACSB URL | Y1: NBA Courses (count) | Z1: NBA Earliest Expiry | AA1: NBA Status | AB1: NBA Domains | AC1: NIRF: Overall | AD1: NIRF: University | AE1: NIRF: Research | AF1: NIRF: Engineering | AG1: NIRF: Management | AH1: NIRF: Pharmacy | AI1: NIRF: Medical | AJ1: NIRF: Dental | AK1: NIRF: Law | AL1: NIRF: Architecture | AM1: NIRF: Agriculture | AN1: NIRF: Innovation | AO1: NIRF: State Public | AP1: NIRF: Open | AQ1: NIRF: Skill | AR1: NIRF: SDG | AS1: NIRF: College | AT1: Verified On | AU1: Notes
A2: 1 | B2: 1 | C2: Andhra Pradesh | D2: State University | E2: Andhra University | F2: Bachelor of Commerce (Accountancy) | G2: B.Com | H2: UG | I2: Online | J2: Yes | K2: Notice 1 (Jan 2026) | L2: AY 2025-26, Jan-Feb 2026 session | N2: =IF(M2="","Active (per Notice 1)",IF(M2<TODAY(),"Expired",IF(M2<TODAY()+180,"Expiring Soon","Active"))) -> Active (per Notice 1) | O2: N/A | P2: A++ | Q2: 3.74 | R2: 4 | S2: 45239 | T2: =IF(S2="","",IF(EDATE(S2,60)<TODAY(),"Expired",IF(EDATE(S2,60)<TODAY()+180,"Expiring Soon","Valid"))) -> Valid | U2: =IF(P2="","",IF(P2="A++","Top Tier",IF(P2="A+","High",IF(P2="A","Strong",IF(LEFT(P2,1)="B","Acceptable",IF(LEFT(P2,1)="C","Below Avg","-")))))) -> Top Tier | AC2: 41 | AD2: 23 | AO2: 4
A3: 2 | B3: 1 | C3: Andhra Pradesh | D3: State University | E3: Andhra University | F3: Bachelor of Arts (History, Economics, Politics) | G3: BA | H3: UG | I3: Online | J3: Yes | K3: Notice 1 (Jan 2026) | L3: AY 2025-26, Jan-Feb 2026 session | N3: =IF(M3="","Active (per Notice 1)",IF(M3<TODAY(),"Expired",IF(M3<TODAY()+180,"Expiring Soon","Active"))) -> Active (per Notice 1) | O3: N/A | P3: A++ | Q3: 3.74 | R3: 4 | S3: 45239 | T3: =IF(S3="","",IF(EDATE(S3,60)<TODAY(),"Expired",IF(EDATE(S3,60)<TODAY()+180,"Expiring Soon","Valid"))) -> Valid | U3: =IF(P3="","",IF(P3="A++","Top Tier",IF(P3="A+","High",IF(P3="A","Strong",IF(LEFT(P3,1)="B","Acceptable",IF(LEFT(P3,1)="C","Below Avg","-")))))) -> Top Tier | AC3: 41 | AD3: 23 | AO3: 4
A4: 3 | B4: 1 | C4: Andhra Pradesh | D4: State University | E4: Andhra University | F4: Bachelor of Commerce | G4: B.Com | H4: UG | I4: Online | J4: Yes | K4: Notice 1 (Jan 2026) | L4: AY 2025-26, Jan-Feb 2026 session | N4: =IF(M4="","Active (per Notice 1)",IF(M4<TODAY(),"Expired",IF(M4<TODAY()+180,"Expiring Soon","Active"))) -> Active (per Notice 1) | O4: N/A | P4: A++ | Q4: 3.74 | R4: 4 | S4: 45239 | T4: =IF(S4="","",IF(EDATE(S4,60)<TODAY(),"Expired",IF(EDATE(S4,60)<TODAY()+180,"Expiring Soon","Valid"))) -> Valid | U4: =IF(P4="","",IF(P4="A++","Top Tier",IF(P4="A+","High",IF(P4="A","Strong",IF(LEFT(P4,1)="B","Acceptable",IF(LEFT(P4,1)="C","Below Avg","-")))))) -> Top Tier | AC4: 41 | AD4: 23 | AO4: 4
A5: 4 | B5: 1 | C5: Andhra Pradesh | D5: State University | E5: Andhra University | F5: Master of Arts (Sociology) | G5: MA | H5: PG | I5: Online | J5: Yes | K5: Notice 1 (Jan 2026) | L5: AY 2025-26, Jan-Feb 2026 session | N5: =IF(M5="","Active (per Notice 1)",IF(M5<TODAY(),"Expired",IF(M5<TODAY()+180,"Expiring Soon","Active"))) -> Active (per Notice 1) | O5: N/A | P5: A++ | Q5: 3.74 | R5: 4 | S5: 45239 | T5: =IF(S5="","",IF(EDATE(S5,60)<TODAY(),"Expired",IF(EDATE(S5,60)<TODAY()+180,"Expiring Soon","Valid"))) -> Valid | U5: =IF(P5="","",IF(P5="A++","Top Tier",IF(P5="A+","High",IF(P5="A","Strong",IF(LEFT(P5,1)="B","Acceptable",IF(LEFT(P5,1)="C","Below Avg","-")))))) -> Top Tier | AC5: 41 | AD5: 23 | AO5: 4
A6: 5 | B6: 1 | C6: Andhra Pradesh | D6: State University | E6: Andhra University | F6: Master of Business Administration | G6: MBA | H6: PG | I6: Online | J6: Yes | K6: Notice 1 (Jan 2026) | L6: AY 2025-26, Jan-Feb 2026 session | N6: =IF(M6="","Active (per Notice 1)",IF(M6<TODAY(),"Expired",IF(M6<TODAY()+180,"Expiring Soon","Active"))) -> Active (per Notice 1) | O6: No | P6: A++ | Q6: 3.74 | R6: 4 | S6: 45239 | T6: =IF(S6="","",IF(EDATE(S6,60)<TODAY(),"Expired",IF(EDATE(S6,60)<TODAY()+180,"Expiring Soon","Valid"))) -> Valid | U6: =IF(P6="","",IF(P6="A++","Top Tier",IF(P6="A+","High",IF(P6="A","Strong",IF(LEFT(P6,1)="B","Acceptable",IF(LEFT(P6,1)="C","Below Avg","-")))))) -> Top Tier | AC6: 41 | AD6: 23 | AO6: 4
A7: 6 | B7: 1 | C7: Andhra Pradesh | D7: State University | E7: Andhra University | F7: Master of Computer Applications | G7: MCA | H7: PG | I7: Online | J7: Yes | K7: Notice 1 (Jan 2026) | L7: AY 2025-26, Jan-Feb 2026 session | N7: =IF(M7="","Active (per Notice 1)",IF(M7<TODAY(),"Expired",IF(M7<TODAY()+180,"Expiring Soon","Active"))) -> Active (per Notice 1) | O7: No | P7: A++ | Q7: 3.74 | R7: 4 | S7: 45239 | T7: =IF(S7="","",IF(EDATE(S7,60)<TODAY(),"Expired",IF(EDATE(S7,60)<TODAY()+180,"Expiring Soon","Valid"))) -> Valid | U7: =IF(P7="","",IF(P7="A++","Top Tier",IF(P7="A+","High",IF(P7="A","Strong",IF(LEFT(P7,1)="B","Acceptable",IF(LEFT(P7,1)="C","Below Avg","-")))))) -> Top Tier | AC7: 41 | AD7: 23 | AO7: 4
A8: 7 | B8: 1 | C8: Andhra Pradesh | D8: State University | E8: Andhra University | F8: Master of Commerce | G8: M.Com | H8: PG | I8: Online | J8: Yes | K8: Notice 1 (Jan 2026) | L8: AY 2025-26, Jan-Feb 2026 session | N8: =IF(M8="","Active (per Notice 1)",IF(M8<TODAY(),"Expired",IF(M8<TODAY()+180,"Expiring Soon","Active"))) -> Active (per Notice 1) | O8: N/A | P8: A++ | Q8: 3.74 | R8: 4 | S8: 45239 | T8: =IF(S8="","",IF(EDATE(S8,60)<TODAY(),"Expired",IF(EDATE(S8,60)<TODAY()+180,"Expiring Soon","Valid"))) -> Valid | U8: =IF(P8="","",IF(P8="A++","Top Tier",IF(P8="A+","High",IF(P8="A","Strong",IF(LEFT(P8,1)="B","Acceptable",IF(LEFT(P8,1)="C","Below Avg","-")))))) -> Top Tier | AC8: 41 | AD8: 23 | AO8: 4
A9: 8 | B9: 1 | C9: Andhra Pradesh | D9: State University | E9: Andhra University | F9: Master of Arts (Political Science) | G9: MA | H9: PG | I9: Online | J9: Yes | K9: Notice 1 (Jan 2026) | L9: AY 2025-26, Jan-Feb 2026 session | N9: =IF(M9="","Active (per Notice 1)",IF(M9<TODAY(),"Expired",IF(M9<TODAY()+180,"Expiring Soon","Active"))) -> Active (per Notice 1) | O9: N/A | P9: A++ | Q9: 3.74 | R9: 4 | S9: 45239 | T9: =IF(S9="","",IF(EDATE(S9,60)<TODAY(),"Expired",IF(EDATE(S9,60)<TODAY()+180,"Expiring Soon","Valid"))) -> Valid | U9: =IF(P9="","",IF(P9="A++","Top Tier",IF(P9="A+","High",IF(P9="A","Strong",IF(LEFT(P9,1)="B","Acceptable",IF(LEFT(P9,1)="C","Below Avg","-")))))) -> Top Tier | AC9: 41 | AD9: 23 | AO9: 4
A10: 9 | B10: 1 | C10: Andhra Pradesh | D10: State University | E10: Andhra University | F10: Master of Arts (Economics) | G10: MA | H10: PG | I10: Online | J10: Yes | K10: Notice 1 (Jan 2026) | L10: AY 2025-26, Jan-Feb 2026 session | N10: =IF(M10="","Active (per Notice 1)",IF(M10<TODAY(),"Expired",IF(M10<TODAY()+180,"Expiring Soon","Active"))) -> Active (per Notice 1) | O10: N/A | P10: A++ | Q10: 3.74 | R10: 4 | S10: 45239 | T10: =IF(S10="","",IF(EDATE(S10,60)<TODAY(),"Expired",IF(EDATE(S10,60)<TODAY()+180,"Expiring Soon","Valid"))) -> Valid | U10: =IF(P10="","",IF(P10="A++","Top Tier",IF(P10="A+","High",IF(P10="A","Strong",IF(LEFT(P10,1)="B","Acceptable",IF(LEFT(P10,1)="C","Below Avg","-")))))) -> Top Tier | AC10: 41 | AD10: 23 | AO10: 4
A11: 10 | B11: 1 | C11: Andhra Pradesh | D11: State University | E11: Andhra University | F11: Master of Arts (English) | G11: MA | H11: PG | I11: Online | J11: Yes | K11: Notice 1 (Jan 2026) | L11: AY 2025-26, Jan-Feb 2026 session | N11: =IF(M11="","Active (per Notice 1)",IF(M11<TODAY(),"Expired",IF(M11<TODAY()+180,"Expiring Soon","Active"))) -> Active (per Notice 1) | O11: N/A | P11: A++ | Q11: 3.74 | R11: 4 | S11: 45239 | T11: =IF(S11="","",IF(EDATE(S11,60)<TODAY(),"Expired",IF(EDATE(S11,60)<TODAY()+180,"Expiring Soon","Valid"))) -> Valid | U11: =IF(P11="","",IF(P11="A++","Top Tier",IF(P11="A+","High",IF(P11="A","Strong",IF(LEFT(P11,1)="B","Acceptable",IF(LEFT(P11,1)="C","Below Avg","-")))))) -> Top Tier | AC11: 41 | AD11: 23 | AO11: 4
A12: 11 | B12: 1 | C12: Andhra Pradesh | D12: State University | E12: Andhra University | F12: Master of Arts (Human Resource Management) | G12: MA | H12: PG | I12: Online | J12: Yes | K12: Notice 1 (Jan 2026) | L12: AY 2025-26, Jan-Feb 2026 session | N12: =IF(M12="","Active (per Notice 1)",IF(M12<TODAY(),"Expired",IF(M12<TODAY()+180,"Expiring Soon","Active"))) -> Active (per Notice 1) | O12: N/A | P12: A++ | Q12: 3.74 | R12: 4 | S12: 45239 | T12: =IF(S12="","",IF(EDATE(S12,60)<TODAY(),"Expired",IF(EDATE(S12,60)<TODAY()+180,"Expiring Soon","Valid"))) -> Valid | U12: =IF(P12="","",IF(P12="A++","Top Tier",IF(P12="A+","High",IF(P12="A","Strong",IF(LEFT(P12,1)="B","Acceptable",IF(LEFT(P12,1)="C","Below Avg","-")))))) -> Top Tier | AC12: 41 | AD12: 23 | AO12: 4
A13: 12 | B13: 1 | C13: Andhra Pradesh | D13: State University | E13: Andhra University | F13: Master of Arts (Journalism & Mass Communication) | G13: MA | H13: PG | I13: Online | J13: Yes | K13: Notice 1 (Jan 2026) | L13: AY 2025-26, Jan-Feb 2026 session | N13: =IF(M13="","Active (per Notice 1)",IF(M13<TODAY(),"Expired",IF(M13<TODAY()+180,"Expiring Soon","Active"))) -> Active (per Notice 1) | O13: N/A | P13: A++ | Q13: 3.74 | R13: 4 | S13: 45239 | T13: =IF(S13="","",IF(EDATE(S13,60)<TODAY(),"Expired",IF(EDATE(S13,60)<TODAY()+180,"Expiring Soon","Valid"))) -> Valid | U13: =IF(P13="","",IF(P13="A++","Top Tier",IF(P13="A+","High",IF(P13="A","Strong",IF(LEFT(P13,1)="B","Acceptable",IF(LEFT(P13,1)="C","Below Avg","-")))))) -> Top Tier | AC13: 41 | AD13: 23 | AO13: 4
A14: 13 | B14: 2 | C14: Andhra Pradesh | D14: Deemed-to-be University | E14: Koneru Lakshmaiah Education Foundation | F14: Bachelor of Business Administration | G14: BBA | H14: UG | I14: Online | J14: Yes | K14: Notice 1 (Jan 2026) | L14: AY 2025-26, Jan-Feb 2026 session | N14: =IF(M14="","Active (per Notice 1)",IF(M14<TODAY(),"Expired",IF(M14<TODAY()+180,"Expiring Soon","Active"))) -> Active (per Notice 1) | O14: Yes | AC14: 46 | AD14: 26 | AF14: 35 | AG14: 70
A15: 14 | B15: 2 | C15: Andhra Pradesh | D15: Deemed-to-be University | E15: Koneru Lakshmaiah Education Foundation | F15: Bachelor of Computer Applications | G15: BCA | H15: UG | I15: Online | J15: Yes | K15: Notice 1 (Jan 2026) | L15: AY 2025-26, Jan-Feb 2026 session | N15: =IF(M15="","Active (per Notice 1)",IF(M15<TODAY(),"Expired",IF(M15<TODAY()+180,"Expiring Soon","Active"))) -> Active (per Notice 1) | O15: Yes | AC15: 46 | AD15: 26 | AF15: 35 | AG15: 70
A16: 15 | B16: 2 | C16: Andhra Pradesh | D16: Deemed-to-be University | E16: Koneru Lakshmaiah Education Foundation | F16: Master of Business Administration (Digital Marketing) | G16: MBA | H16: PG | I16: Online | J16: Yes | K16: Notice 1 (Jan 2026) | L16: AY 2025-26, Jan-Feb 2026 session | N16: =IF(M16="","Active (per Notice 1)",IF(M16<TODAY(),"Expired",IF(M16<TODAY()+180,"Expiring Soon","Active"))) -> Active (per Notice 1) | O16: Yes | AC16: 46 | AD16: 26 | AF16: 35 | AG16: 70
A17: 16 | B17: 2 | C17: Andhra Pradesh | D17: Deemed-to-be University | E17: Koneru Lakshmaiah Education Foundation | F17: Master of Business Administration (Entrepreneurship) | G17: MBA | H17: PG | I17: Online | J17: Yes | K17: Notice 1 (Jan 2026) | L17: AY 2025-26, Jan-Feb 2026 session | N17: =IF(M17="","Active (per Notice 1)",IF(M17<TODAY(),"Expired",IF(M17<TODAY()+180,"Expiring Soon","Active"))) -> Active (per Notice 1) | O17: Yes | AC17: 46 | AD17: 26 | AF17: 35 | AG17: 70
A18: 17 | B18: 2 | C18: Andhra Pradesh | D18: Deemed-to-be University | E18: Koneru Lakshmaiah Education Foundation | F18: Master of Business Administration (Data Science) | G18: MBA | H18: PG | I18: Online | J18: Yes | K18: Notice 1 (Jan 2026) | L18: AY 2025-26, Jan-Feb 2026 session | N18: =IF(M18="","Active (per Notice 1)",IF(M18<TODAY(),"Expired",IF(M18<TODAY()+180,"Expiring Soon","Active"))) -> Active (per Notice 1) | O18: Yes | AC18: 46 | AD18: 26 | AF18: 35 | AG18: 70
A19: 18 | B19: 2 | C19: Andhra Pradesh | D19: Deemed-to-be University | E19: Koneru Lakshmaiah Education Foundation | F19: Master of Business Administration (Logistics & Supply Chain Management) | G19: MBA | H19: PG | I19: Online | J19: Yes | K19: Notice 1 (Jan 2026) | L19: AY 2025-26, Jan-Feb 2026 session | N19: =IF(M19="","Active (per Notice 1)",IF(M19<TODAY(),"Expired",IF(M19<TODAY()+180,"Expiring Soon","Active"))) -> Active (per Notice 1) | O19: Yes | AC19: 46 | AD19: 26 | AF19: 35 | AG19: 70
A20: 19 | B20: 2 | C20: Andhra Pradesh | D20: Deemed-to-be University | E20: Koneru Lakshmaiah Education Foundation | F20: Master of Business Administration | G20: MBA | H20: PG | I20: Online | J20: Yes | K20: Notice 1 (Jan 2026) | L20: AY 2025-26, Jan-Feb 2026 session | N20: =IF(M20="","Active (per Notice 1)",IF(M20<TODAY(),"Expired",IF(M20<TODAY()+180,"Expiring Soon","Active"))) -> Active (per Notice 1) | O20: Yes | AC20: 46 | AD20: 26 | AF20: 35 | AG20: 70
A21: 20 | B21: 2 | C21: Andhra Pradesh | D21: Deemed-to-be University | E21: Koneru Lakshmaiah Education Foundation | F21: Master of Computer Applications | G21: MCA | H21: PG | I21: Online | J21: Yes | K21: Notice 1 (Jan 2026) | L21: AY 2025-26, Jan-Feb 2026 session | N21: =IF(M21="","Active (per Notice 1)",IF(M21<TODAY(),"Expired",IF(M21<TODAY()+180,"Expiring Soon","Active"))) -> Active (per Notice 1) | O21: Yes | AC21: 46 | AD21: 26 | AF21: 35 | AG21: 70
A22: 21 | B22: 3 | C22: Andhra Pradesh | D22: Deemed-to-be University | E22: Vignan's Foundation for Science, Technology and Research | F22: Bachelor of Business Administration (General) | G22: BBA | H22: UG | I22: Online | J22: Yes | K22: Notice 1 (Jan 2026) | L22: AY 2025-26, Jan-Feb 2026 session | N22: =IF(M22="","Active (per Notice 1)",IF(M22<TODAY(),"Expired",IF(M22<TODAY()+180,"Expiring Soon","Active"))) -> Active (per Notice 1) | O22: Yes | P22: A+ | Q22: 3.49 | R22: 2 | S22: 44495 | T22: =IF(S22="","",IF(EDATE(S22,60)<TODAY(),"Expired",IF(EDATE(S22,60)<TODAY()+180,"Expiring Soon","Valid"))) -> Valid | U22: =IF(P22="","",IF(P22="A++","Top Tier",IF(P22="A+","High",IF(P22="A","Strong",IF(LEFT(P22,1)="B","Acceptable",IF(LEFT(P22,1)="C","Below Avg","-")))))) -> High | Y22: 4 | Z22: 46203 | AA22: All Valid | AB22: Engg | AD22: 70 | AF22: 80
A23: 22 | B23: 3 | C23: Andhra Pradesh | D23: Deemed-to-be University | E23: Vignan's Foundation for Science, Technology and Research | F23: Bachelor of Computer Applications | G23: BCA | H23: UG | I23: Online | J23: Yes | K23: Notice 1 (Jan 2026) | L23: AY 2025-26, Jan-Feb 2026 session | N23: =IF(M23="","Active (per Notice 1)",IF(M23<TODAY(),"Expired",IF(M23<TODAY()+180,"Expiring Soon","Active"))) -> Active (per Notice 1) | O23: Yes | P23: A+ | Q23: 3.49 | R23: 2 | S23: 44495 | T23: =IF(S23="","",IF(EDATE(S23,60)<TODAY(),"Expired",IF(EDATE(S23,60)<TODAY()+180,"Expiring Soon","Valid"))) -> Valid | U23: =IF(P23="","",IF(P23="A++","Top Tier",IF(P23="A+","High",IF(P23="A","Strong",IF(LEFT(P23,1)="B","Acceptable",IF(LEFT(P23,1)="C","Below Avg","-")))))) -> High | Y23: 4 | Z23: 46203 | AA23: All Valid | AB23: Engg | AD23: 70 | AF23: 80
A24: 23 | B24: 3 | C24: Andhra Pradesh | D24: Deemed-to-be University | E24: Vignan's Foundation for Science, Technology and Research | F24: Master of Business Administration (HR) | G24: MBA | H24: PG | I24: Online | J24: Yes | K24: Notice 1 (Jan 2026) | L24: AY 2025-26, Jan-Feb 2026 session | N24: =IF(M24="","Active (per Notice 1)",IF(M24<TODAY(),"Expired",IF(M24<TODAY()+180,"Expiring Soon","Active"))) -> Active (per Notice 1) | O24: Yes | P24: A+ | Q24: 3.49 | R24: 2 | S24: 44495 | T24: =IF(S24="","",IF(EDATE(S24,60)<TODAY(),"Expired",IF(EDATE(S24,60)<TODAY()+180,"Expiring Soon","Valid"))) -> Valid | U24: =IF(P24="","",IF(P24="A++","Top Tier",IF(P24="A+","High",IF(P24="A","Strong",IF(LEFT(P24,1)="B","Acceptable",IF(LEFT(P24,1)="C","Below Avg","-")))))) -> High | Y24: 4 | Z24: 46203 | AA24: All Valid | AB24: Engg | AD24: 70 | AF24: 80
A25: 24 | B25: 3 | C25: Andhra Pradesh | D25: Deemed-to-be University | E25: Vignan's Foundation for Science, Technology and Research | F25: Master of Business Administration (Finance) | G25: MBA | H25: PG | I25: Online | J25: Yes | K25: Notice 1 (Jan 2026) | L25: AY 2025-26, Jan-Feb 2026 session | N25: =IF(M25="","Active (per Notice 1)",IF(M25<TODAY(),"Expired",IF(M25<TODAY()+180,"Expiring Soon","Active"))) -> Active (per Notice 1) | O25: Yes | P25: A+ | Q25: 3.49 | R25: 2 | S25: 44495 | T25: =IF(S25="","",IF(EDATE(S25,60)<TODAY(),"Expired",IF(EDATE(S25,60)<TODAY()+180,"Expiring Soon","Valid"))) -> Valid | U25: =IF(P25="","",IF(P25="A++","Top Tier",IF(P25="A+","High",IF(P25="A","Strong",IF(LEFT(P25,1)="B","Acceptable",IF(LEFT(P25,1)="C","Below Avg","-")))))) -> High | Y25: 4 | Z25: 46203 | AA25: All Valid | AB25: Engg | AD25: 70 | AF25: 80
A26: 25 | B26: 3 | C26: Andhra Pradesh | D26: Deemed-to-be University | E26: Vignan's Foundation for Science, Technology and Research | F26: Master of Business Administration (General) | G26: MBA | H26: PG | I26: Online | J26: Yes | K26: Notice 1 (Jan 2026) | L26: AY 2025-26, Jan-Feb 2026 session | N26: =IF(M26="","Active (per Notice 1)",IF(M26<TODAY(),"Expired",IF(M26<TODAY()+180,"Expiring Soon","Active"))) -> Active (per Notice 1) | O26: Yes | P26: A+ | Q26: 3.49 | R26: 2 | S26: 44495 | T26: =IF(S26="","",IF(EDATE(S26,60)<TODAY(),"Expired",IF(EDATE(S26,60)<TODAY()+180,"Expiring Soon","Valid"))) -> Valid | U26: =IF(P26="","",IF(P26="A++","Top Tier",IF(P26="A+","High",IF(P26="A","Strong",IF(LEFT(P26,1)="B","Acceptable",IF(LEFT(P26,1)="C","Below Avg","-")))))) -> High | Y26: 4 | Z26: 46203 | AA26: All Valid | AB26: Engg | AD26: 70 | AF26: 80
A27: 26 | B27: 3 | C27: Andhra Pradesh | D27: Deemed-to-be University | E27: Vignan's Foundation for Science, Technology and Research | F27: Master of Computer Applications | G27: MCA | H27: PG | I27: Online | J27: Yes | K27: Notice 1 (Jan 2026) | L27: AY 2025-26, Jan-Feb 2026 session | N27: =IF(M27="","Active (per Notice 1)",IF(M27<TODAY(),"Expired",IF(M27<TODAY()+180,"Expiring Soon","Active"))) -> Active (per Notice 1) | O27: Yes | P27: A+ | Q27: 3.49 | R27: 2 | S27: 44495 | T27: =IF(S27="","",IF(EDATE(S27,60)<TODAY(),"Expired",IF(EDATE(S27,60)<TODAY()+180,"Expiring Soon","Valid"))) -> Valid | U27: =IF(P27="","",IF(P27="A++","Top Tier",IF(P27="A+","High",IF(P27="A","Strong",IF(LEFT(P27,1)="B","Acceptable",IF(LEFT(P27,1)="C","Below Avg","-")))))) -> High | Y27: 4 | Z27: 46203 | AA27: All Valid | AB27: Engg | AD27: 70 | AF27: 80
A28: 27 | B28: 4 | C28: Andhra Pradesh | D28: Private University | E28: Mohan Babu University | F28: Bachelor of Commerce | G28: B.Com | H28: UG | I28: Online | J28: Yes | K28: Notice 1 (Jan 2026) | L28: AY 2025-26, Jan-Feb 2026 session | N28: =IF(M28="","Active (per Notice 1)",IF(M28<TODAY(),"Expired",IF(M28<TODAY()+180,"Expiring Soon","Active"))) -> Active (per Notice 1) | O28: N/A
A29: 28 | B29: 4 | C29: Andhra Pradesh | D29: Private University | E29: Mohan Babu University | F29: Bachelor of Business Administration | G29: BBA | H29: UG | I29: Online | J29: Yes | K29: Notice 1 (Jan 2026) | L29: AY 2025-26, Jan-Feb 2026 session | N29: =IF(M29="","Active (per Notice 1)",IF(M29<TODAY(),"Expired",IF(M29<TODAY()+180,"Expiring Soon","Active"))) -> Active (per Notice 1) | O29: No
A30: 29 | B30: 4 | C30: Andhra Pradesh | D30: Private University | E30: Mohan Babu University | F30: Bachelor of Computer Applications | G30: BCA | H30: UG | I30: Online | J30: Yes | K30: Notice 1 (Jan 2026) | L30: AY 2025-26, Jan-Feb 2026 session | N30: =IF(M30="","Active (per Notice 1)",IF(M30<TODAY(),"Expired",IF(M30<TODAY()+180,"Expiring Soon","Active"))) -> Active (per Notice 1) | O30: No
A31: 30 | B31: 4 | C31: Andhra Pradesh | D31: Private University | E31: Mohan Babu University | F31: Master of Business Administration | G31: MBA | H31: PG | I31: Online | J31: Yes | K31: Notice 1 (Jan 2026) | L31: AY 2025-26, Jan-Feb 2026 session | N31: =IF(M31="","Active (per Notice 1)",IF(M31<TODAY(),"Expired",IF(M31<TODAY()+180,"Expiring Soon","Active"))) -> Active (per Notice 1) | O31: No
A32: 31 | B32: 4 | C32: Andhra Pradesh | D32: Private University | E32: Mohan Babu University | F32: Master of Computer Applications | G32: MCA | H32: PG | I32: Online | J32: Yes | K32: Notice 1 (Jan 2026) | L32: AY 2025-26, Jan-Feb 2026 session | N32: =IF(M32="","Active (per Notice 1)",IF(M32<TODAY(),"Expired",IF(M32<TODAY()+180,"Expiring Soon","Active"))) -> Active (per Notice 1) | O32: No
A33: 32 | B33: 5 | C33: Assam | D33: Private University | E33: Assam Down Town University | F33: Bachelor of Business Administration | G33: BBA | H33: UG | I33: Online | J33: Yes | K33: Notice 1 (Jan 2026) | L33: AY 2025-26, Jan-Feb 2026 session | N33: =IF(M33="","Active (per Notice 1)",IF(M33<TODAY(),"Expired",IF(M33<TODAY()+180,"Expiring Soon","Active"))) -> Active (per Notice 1) | O33: No | P33: A+ | Q33: 3.34 | R33: 2 | S33: 45786 | T33: =IF(S33="","",IF(EDATE(S33,60)<TODAY(),"Expired",IF(EDATE(S33,60)<TODAY()+180,"Expiring Soon","Valid"))) -> Valid | U33: =IF(P33="","",IF(P33="A++","Top Tier",IF(P33="A+","High",IF(P33="A","Strong",IF(LEFT(P33,1)="B","Acceptable",IF(LEFT(P33,1)="C","Below Avg","-")))))) -> High
A34: 33 | B34: 5 | C34: Assam | D34: Private University | E34: Assam Down Town University | F34: Bachelor of Computer Applications | G34: BCA | H34: UG | I34: Online | J34: Yes | K34: Notice 1 (Jan 2026) | L34: AY 2025-26, Jan-Feb 2026 session | N34: =IF(M34="","Active (per Notice 1)",IF(M34<TODAY(),"Expired",IF(M34<TODAY()+180,"Expiring Soon","Active"))) -> Active (per Notice 1) | O34: No | P34: A+ | Q34: 3.34 | R34: 2 | S34: 45786 | T34: =IF(S34="","",IF(EDATE(S34,60)<TODAY(),"Expired",IF(EDATE(S34,60)<TODAY()+180,"Expiring Soon","Valid"))) -> Valid | U34: =IF(P34="","",IF(P34="A++","Top Tier",IF(P34="A+","High",IF(P34="A","Strong",IF(LEFT(P34,1)="B","Acceptable",IF(LEFT(P34,1)="C","Below Avg","-")))))) -> High
A35: 34 | B35: 5 | C35: Assam | D35: Private University | E35: Assam Down Town University | F35: Master of Computer Applications | G35: MCA | H35: PG | I35: Online | J35: Yes | K35: Notice 1 (Jan 2026) | L35: AY 2025-26, Jan-Feb 2026 session | N35: =IF(M35="","Active (per Notice 1)",IF(M35<TODAY(),"Expired",IF(M35<TODAY()+180,"Expiring Soon","Active"))) -> Active (per Notice 1) | O35: No | P35: A+ | Q35: 3.34 | R35: 2 | S35: 45786 | T35: =IF(S35="","",IF(EDATE(S35,60)<TODAY(),"Expired",IF(EDATE(S35,60)<TODAY()+180,"Expiring Soon","Valid"))) -> Valid | U35: =IF(P35="","",IF(P35="A++","Top Tier",IF(P35="A+","High",IF(P35="A","Strong",IF(LEFT(P35,1)="B","Acceptable",IF(LEFT(P35,1)="C","Below Avg","-")))))) -> High
A36: 35 | B36: 5 | C36: Assam | D36: Private University | E36: Assam Down Town University | F36: Master of Business Administration | G36: MBA | H36: PG | I36: Online | J36: Yes | K36: Notice 1 (Jan 2026) | L36: AY 2025-26, Jan-Feb 2026 session | N36: =IF(M36="","Active (per Notice 1)",IF(M36<TODAY(),"Expired",IF(M36<TODAY()+180,"Expiring Soon","Active"))) -> Active (per Notice 1) | O36: No | P36: A+ | Q36: 3.34 | R36: 2 | S36: 45786 | T36: =IF(S36="","",IF(EDATE(S36,60)<TODAY(),"Expired",IF(EDATE(S36,60)<TODAY()+180,"Expiring Soon","Valid"))) -> Valid | U36: =IF(P36="","",IF(P36="A++","Top Tier",IF(P36="A+","High",IF(P36="A","Strong",IF(LEFT(P36,1)="B","Acceptable",IF(LEFT(P36,1)="C","Below Avg","-")))))) -> High
A37: 36 | B37: 6 | C37: Chhattisgarh | D37: Central University | E37: Guru Ghasidas Vishwavidyalaya | F37: Bachelor of Computer Applications | G37: BCA | H37: UG | I37: Online | J37: Yes | K37: Notice 1 (Jan 2026) | L37: AY 2025-26, Jan-Feb 2026 session | N37: =IF(M37="","Active (per Notice 1)",IF(M37<TODAY(),"Expired",IF(M37<TODAY()+180,"Expiring Soon","Active"))) -> Active (per Notice 1) | O37: No | P37: A++ | Q37: 3.62 | R37: 2 | S37: 45407 | T37: =IF(S37="","",IF(EDATE(S37,60)<TODAY(),"Expired",IF(EDATE(S37,60)<TODAY()+180,"Expiring Soon","Valid"))) -> Valid | U37: =IF(P37="","",IF(P37="A++","Top Tier",IF(P37="A+","High",IF(P37="A","Strong",IF(LEFT(P37,1)="B","Acceptable",IF(LEFT(P37,1)="C","Below Avg","-")))))) -> Top Tier | AH37: 47
A38: 37 | B38: 6 | C38: Chhattisgarh | D38: Central University | E38: Guru Ghasidas Vishwavidyalaya | F38: Bachelor of Commerce (Hons) | G38: B.Com | H38: UG | I38: Online | J38: Yes | K38: Notice 1 (Jan 2026) | L38: AY 2025-26, Jan-Feb 2026 session | N38: =IF(M38="","Active (per Notice 1)",IF(M38<TODAY(),"Expired",IF(M38<TODAY()+180,"Expiring Soon","Active"))) -> Active (per Notice 1) | O38: N/A | P38: A++ | Q38: 3.62 | R38: 2 | S38: 45407 | T38: =IF(S38="","",IF(EDATE(S38,60)<TODAY(),"Expired",IF(EDATE(S38,60)<TODAY()+180,"Expiring Soon","Valid"))) -> Valid | U38: =IF(P38="","",IF(P38="A++","Top Tier",IF(P38="A+","High",IF(P38="A","Strong",IF(LEFT(P38,1)="B","Acceptable",IF(LEFT(P38,1)="C","Below Avg","-")))))) -> Top Tier | AH38: 47
A39: 38 | B39: 6 | C39: Chhattisgarh | D39: Central University | E39: Guru Ghasidas Vishwavidyalaya | F39: Bachelor of Library & Information Sciences | G39: BLIS | H39: UG | I39: Online | J39: Yes | K39: Notice 1 (Jan 2026) | L39: AY 2025-26, Jan-Feb 2026 session | N39: =IF(M39="","Active (per Notice 1)",IF(M39<TODAY(),"Expired",IF(M39<TODAY()+180,"Expiring Soon","Active"))) -> Active (per Notice 1) | O39: N/A | P39: A++ | Q39: 3.62 | R39: 2 | S39: 45407 | T39: =IF(S39="","",IF(EDATE(S39,60)<TODAY(),"Expired",IF(EDATE(S39,60)<TODAY()+180,"Expiring Soon","Valid"))) -> Valid | U39: =IF(P39="","",IF(P39="A++","Top Tier",IF(P39="A+","High",IF(P39="A","Strong",IF(LEFT(P39,1)="B","Acceptable",IF(LEFT(P39,1)="C","Below Avg","-")))))) -> Top Tier | AH39: 47
A40: 39 | B40: 6 | C40: Chhattisgarh | D40: Central University | E40: Guru Ghasidas Vishwavidyalaya | F40: Master of Social Work | G40: MSW | H40: PG | I40: Online | J40: Yes | K40: Notice 1 (Jan 2026) | L40: AY 2025-26, Jan-Feb 2026 session | N40: =IF(M40="","Active (per Notice 1)",IF(M40<TODAY(),"Expired",IF(M40<TODAY()+180,"Expiring Soon","Active"))) -> Active (per Notice 1) | O40: N/A | P40: A++ | Q40: 3.62 | R40: 2 | S40: 45407 | T40: =IF(S40="","",IF(EDATE(S40,60)<TODAY(),"Expired",IF(EDATE(S40,60)<TODAY()+180,"Expiring Soon","Valid"))) -> Valid | U40: =IF(P40="","",IF(P40="A++","Top Tier",IF(P40="A+","High",IF(P40="A","Strong",IF(LEFT(P40,1)="B","Acceptable",IF(LEFT(P40,1)="C","Below Avg","-")))))) -> Top Tier | AH40: 47
...

Sheet University_Summary
A1: S.No | B1: UGC S.No | C1: State | D1: HEI Type | E1: University Name | F1: Programme Count (Online) | G1: UGC-DEB Status | H1: NAAC Grade | I1: NAAC CGPA | J1: NIRF Rank (Univ.) | K1: NIRF Rank (Mgmt.) | L1: NIRF Year | M1: Official Website | N1: AACSB B-school | O1: NBA Courses | P1: NBA Status | Q1: Notes
A2: 1 | B2: 1 | C2: Andhra Pradesh | D2: State University | E2: Andhra University | F2: =COUNTIF(Master_Online!E:E,E2) -> 12 | G2: Approved | H2: A++ | I2: 3.74 | J2: 23 | L2: 2025
A3: 2 | B3: 2 | C3: Andhra Pradesh | D3: Deemed-to-be University | E3: Koneru Lakshmaiah Education Foundation | F3: =COUNTIF(Master_Online!E:E,E3) -> 8 | G3: Approved | J3: 26 | K3: 70 | L3: 2025
A4: 3 | B4: 3 | C4: Andhra Pradesh | D4: Deemed-to-be University | E4: Vignan's Foundation for Science, Technology and Research | F4: =COUNTIF(Master_Online!E:E,E4) -> 6 | G4: Approved | H4: A+ | I4: 3.49 | J4: 70 | L4: 2025 | O4: 4 | P4: All Valid
A5: 4 | B5: 4 | C5: Andhra Pradesh | D5: Private University | E5: Mohan Babu University | F5: =COUNTIF(Master_Online!E:E,E5) -> 5 | G5: Approved
A6: 5 | B6: 5 | C6: Assam | D6: Private University | E6: Assam Down Town University | F6: =COUNTIF(Master_Online!E:E,E6) -> 4 | G6: Approved | H6: A+ | I6: 3.34
A7: 6 | B7: 6 | C7: Chhattisgarh | D7: Central University | E7: Guru Ghasidas Vishwavidyalaya | F7: =COUNTIF(Master_Online!E:E,E7) -> 13 | G7: Approved | H7: A++ | I7: 3.62 | L7: 2025
A8: 7 | B8: 7 | C8: Chhattisgarh | D8: Private University | E8: MATS University | F8: =COUNTIF(Master_Online!E:E,E8) -> 5 | G8: Approved | H8: A+ | I8: 3.3
A9: 8 | B9: 8 | C9: Delhi | D9: Deemed-to-be University | E9: Jamia Hamdard | F9: =COUNTIF(Master_Online!E:E,E9) -> 8 | G9: Approved | H9: A+ | I9: 3.41 | J9: 47 | K9: 87 | L9: 2025
A10: 9 | B10: 9 | C10: Delhi | D10: Central University | E10: Jamia Millia Islamia University | F10: =COUNTIF(Master_Online!E:E,E10) -> 12 | G10: Approved | H10: A++ | I10: 3.61 | J10: 4 | K10: 28 | L10: 2025 | O10: 7 | P10: Mixed
A11: 10 | B11: 10 | C11: Delhi | D11: Central University | E11: Jawaharlal Nehru University | F11: =COUNTIF(Master_Online!E:E,E11) -> 1 | G11: Approved | H11: A++ | I11: 3.62 | J11: 2 | L11: 2025
A12: 11 | B12: 11 | C12: Delhi | D12: Central University | E12: Central Sanskrit University | F12: =COUNTIF(Master_Online!E:E,E12) -> 6 | G12: Approved | H12: A++ | I12: 3.6
A13: 12 | B13: 12 | C13: Delhi | D13: State University | E13: Guru Gobind Singh Indraprastha Vishwavidyalaya | F13: =COUNTIF(Master_Online!E:E,E13) -> 4 | G13: Approved | H13: A++ | I13: 3.56 | J13: 93 | K13: 76 | L13: 2025
A14: 13 | B14: 13 | C14: Delhi | D14: Deemed-to-be University | E14: Indian Institute of Foreign Trade | F14: =COUNTIF(Master_Online!E:E,E14) -> 1 | G14: Approved | H14: A+ | I14: 3.27 | K14: 17 | L14: 2025 | N14: Accredited
A15: 14 | B15: 14 | C15: Gujarat | D15: State University | E15: Gujarat University | F15: =COUNTIF(Master_Online!E:E,E15) -> 6 | G15: Approved | H15: A+ | I15: 3.3 | J15: 74 | L15: 2025
A16: 15 | B16: 15 | C16: Gujarat | D16: Private University | E16: Charotar University of Science & Technology | F16: =COUNTIF(Master_Online!E:E,E16) -> 4 | G16: Approved | H16: A+ | I16: 3.26
A17: 16 | B17: 16 | C17: Gujarat | D17: State Open University | E17: Dr. Babasaheb Ambedkar Open University | F17: =COUNTIF(Master_Online!E:E,E17) -> 10 | G17: Approved | H17: A++ | I17: 3.55
A18: 17 | B18: 17 | C18: Gujarat | D18: Private University | E18: Parul University | F18: =COUNTIF(Master_Online!E:E,E18) -> 10 | G18: Approved | H18: A++ | I18: 3.55 | L18: 2025
A19: 18 | B19: 18 | C19: Gujarat | D19: Private University | E19: Marwadi University | F19: =COUNTIF(Master_Online!E:E,E19) -> 7 | G19: Approved | H19: A+ | I19: 3.31
A20: 19 | B20: 19 | C20: Gujarat | D20: State University | E20: Gujarat Technological University | F20: =COUNTIF(Master_Online!E:E,E20) -> 1 | G20: Approved | H20: A+ | I20: 3.26 | L20: 2025
A21: 20 | B21: 20 | C21: Gujarat | D21: Private University | E21: G.L.S. University | F21: =COUNTIF(Master_Online!E:E,E21) -> 6 | G21: Approved | H21: A+ | I21: 3.44
A22: 21 | B22: 21 | C22: Gujarat | D22: Private University | E22: P.P. Savani University | F22: =COUNTIF(Master_Online!E:E,E22) -> 5 | G22: Approved | H22: A+ | I22: 3.38
A23: 22 | B23: 22 | C23: Haryana | D23: State University | E23: Guru Jambheshwar University of Science and Technology | F23: =COUNTIF(Master_Online!E:E,E23) -> 8 | G23: Approved | H23: A+ | I23: 3.38 | L23: 2025 | O23: 6 | P23: All Expired
A24: 23 | B24: 23 | C24: Haryana | D24: State University | E24: Kurukshetra University | F24: =COUNTIF(Master_Online!E:E,E24) -> 9 | G24: Approved | H24: A++ | I24: 3.56 | L24: 2025
A25: 24 | B25: 24 | C25: Haryana | D25: State University | E25: Maharshi Dayanand University | F25: =COUNTIF(Master_Online!E:E,E25) -> 8 | G25: Approved | L25: 2025
A26: 25 | B26: 25 | C26: Haryana | D26: Deemed-to-be University | E26: Maharishi Markandeshwar | F26: =COUNTIF(Master_Online!E:E,E26) -> 6 | G26: Approved | H26: A++ | I26: 3.53 | J26: 85 | L26: 2025 | O26: 2 | P26: All Valid
A27: 26 | B27: 26 | C27: Haryana | D27: Deemed-to-be University | E27: Manav Rachna International Institute of Research & Studies | F27: =COUNTIF(Master_Online!E:E,E27) -> 10 | G27: Approved | H27: A++ | I27: 3.53 | J27: 96 | L27: 2025 | O27: 2 | P27: All Expired
A28: 27 | B28: 27 | C28: Haryana | D28: Private University | E28: Shree Guru Gobind Singh Tricentenary University | F28: =COUNTIF(Master_Online!E:E,E28) -> 5 | G28: Approved | H28: A+ | I28: 3.33 | L28: 2025
A29: 28 | B29: 28 | C29: Himachal Pradesh | D29: Private University | E29: Shoolini University of Biotechnology and Management Sciences | F29: =COUNTIF(Master_Online!E:E,E29) -> 8 | G29: Approved | H29: A+ | I29: 3.3 | J29: 69 | L29: 2025
A30: 29 | B30: 29 | C30: Himachal Pradesh | D30: Central University | E30: Central University of Himachal Pradesh | F30: =COUNTIF(Master_Online!E:E,E30) -> 5 | G30: Approved | H30: A+ | I30: 3.42
A31: 30 | B31: 30 | C31: Jammu & Kashmir | D31: State University | E31: University of Jammu | F31: =COUNTIF(Master_Online!E:E,E31) -> 2 | G31: Approved | H31: A++ | I31: 3.72 | J31: 51 | L31: 2025
A32: 31 | B32: 31 | C32: Jharkhand | D32: Deemed-to-be University | E32: Birla Institute of Technology | F32: =COUNTIF(Master_Online!E:E,E32) -> 1 | G32: Approved | H32: A | I32: 3.17 | J32: 92 | K32: 97 | L32: 2025 | O32: 8 | P32: Mixed
A33: 32 | B33: 32 | C33: Karnataka | D33: Deemed-to-be University | E33: Jain (Deemed-to-be University) | F33: =COUNTIF(Master_Online!E:E,E33) -> 11 | G33: Approved | H33: A | I33: 3.15 | J33: 62 | K33: 73 | L33: 2025
A34: 33 | B34: 33 | C34: Karnataka | D34: Deemed-to-be University | E34: JSS Academy of Education and Research | F34: =COUNTIF(Master_Online!E:E,E34) -> 3 | G34: Approved | H34: A++ | I34: 3.61 | J34: 21 | L34: 2025
A35: 34 | B35: 34 | C35: Karnataka | D35: Deemed-to-be University | E35: Manipal Academy of Higher Education | F35: =COUNTIF(Master_Online!E:E,E35) -> 7 | G35: Approved | H35: A++ | I35: 3.65 | J35: 3 | L35: 2025 | N35: Accredited
A36: 35 | B36: 35 | C36: Karnataka | D36: State University | E36: Bangalore University | F36: =COUNTIF(Master_Online!E:E,E36) -> 10 | G36: Approved | H36: A++ | I36: 3.75 | J36: 65 | L36: 2025
A37: 36 | B37: 36 | C37: Karnataka | D37: State University | E37: University of Mysore | F37: =COUNTIF(Master_Online!E:E,E37) -> 12 | G37: Approved | H37: A | I37: 3.01 | J37: 71 | L37: 2025
A38: 37 | B38: 37 | C38: Karnataka | D38: Deemed-to-be University | E38: Yenepoya | F38: =COUNTIF(Master_Online!E:E,E38) -> 6 | G38: Approved | H38: A+ | I38: 3.47
A39: 38 | B39: 38 | C39: Karnataka | D39: State University | E39: Visvesvaraya Technological University | F39: =COUNTIF(Master_Online!E:E,E39) -> 13 | G39: Approved | H39: B+ | I39: 2.73 | L39: 2025
A40: 39 | B40: 39 | C40: Karnataka | D40: State Open University | E40: Karnataka State Open University | F40: =COUNTIF(Master_Online!E:E,E40) -> 10 | G40: Approved | H40: A+ | I40: 3.31 | L40: 2025
...

Sheet Verification_Lookup
A1: UGC-DEB Online Programme Verification
A2: Type or paste a university name in B4 to verify UGC-DEB online approval.
A4: University Name (input): | B4: Lovely Professional University
A6: UGC-DEB Approved? | B6: =IF(COUNTIF(Master_Online!E:E,B4)>0,"YES — Approved","NOT FOUND in UGC-DEB online list") -> YES — Approved
A7: Number of Online Programmes Approved | B7: =COUNTIF(Master_Online!E:E,B4) -> 12
A8: State | B8: =IFERROR(INDEX(Master_Online!C:C,MATCH(B4,Master_Online!E:E,0)),"-") -> Punjab
A9: HEI Type | B9: =IFERROR(INDEX(Master_Online!D:D,MATCH(B4,Master_Online!E:E,0)),"-") -> Private University
A10: UGC S.No (in notice) | B10: =IFERROR(INDEX(Master_Online!B:B,MATCH(B4,Master_Online!E:E,0)),"-") -> 62
A11: MBA Online Approved? | B11: =IF(COUNTIFS(Master_Online!E:E,B4,Master_Online!G:G,"MBA")>0,"YES","NO") -> YES
A12: MCA Online Approved? | B12: =IF(COUNTIFS(Master_Online!E:E,B4,Master_Online!G:G,"MCA")>0,"YES","NO") -> YES
A13: BBA Online Approved? | B13: =IF(COUNTIFS(Master_Online!E:E,B4,Master_Online!G:G,"BBA")>0,"YES","NO") -> YES
A14: BCA Online Approved? | B14: =IF(COUNTIFS(Master_Online!E:E,B4,Master_Online!G:G,"BCA")>0,"YES","NO") -> YES
A16: Validity Status (latest match): | B16: =IFERROR(INDEX(Master_Online!N:N,MATCH(B4,Master_Online!E:E,0)),"-") -> Active (per Notice 1)
A17: Source Notice (latest match): | B17: =IFERROR(INDEX(Master_Online!K:K,MATCH(B4,Master_Online!E:E,0)),"-") -> Notice 1 (Jan 2026)
A18: =IFERROR(textjoin(CHAR(10),TRUE(),IF(Master_Online!E2:E2000=B4,Master_Online!F2:F2000,"")),"No matching programmes") -> No matching programmes
A40: AICTE Approved (MBA)? | B40: =IF(COUNTIFS(Master_Online!E:E,B4,Master_Online!G:G,"MBA",Master_Online!O:O,"Yes")>0,"YES","NO / N-A") -> NO / N-A
A41: AICTE Approved (MCA)? | B41: =IF(COUNTIFS(Master_Online!E:E,B4,Master_Online!G:G,"MCA",Master_Online!O:O,"Yes")>0,"YES","NO / N-A") -> NO / N-A
A42: AICTE Approved (BBA)? | B42: =IF(COUNTIFS(Master_Online!E:E,B4,Master_Online!G:G,"BBA",Master_Online!O:O,"Yes")>0,"YES","NO / N-A") -> NO / N-A
A43: AICTE Approved (BCA)? | B43: =IF(COUNTIFS(Master_Online!E:E,B4,Master_Online!G:G,"BCA",Master_Online!O:O,"Yes")>0,"YES","NO / N-A") -> NO / N-A
A45: NIRF 2025 — Overall Rank: | B45: =IFERROR(VLOOKUP(B4,NIRF_All_Rankings!D5:W200,4,FALSE()),"—") -> 49
A46: NIRF 2025 — University Rank: | B46: =IFERROR(VLOOKUP(B4,NIRF_All_Rankings!D5:W200,5,FALSE()),"—") -> 31
A47: NIRF 2025 — Research Rank: | B47: =IFERROR(VLOOKUP(B4,NIRF_All_Rankings!D5:W200,6,FALSE()),"—") -> 40
A48: NIRF 2025 — Engineering Rank: | B48: =IFERROR(VLOOKUP(B4,NIRF_All_Rankings!D5:W200,7,FALSE()),"—") -> 48
A49: NIRF 2025 — Management Rank: | B49: =IFERROR(VLOOKUP(B4,NIRF_All_Rankings!D5:W200,8,FALSE()),"—") -> 44
A50: NIRF 2025 — Pharmacy Rank: | B50: =IFERROR(VLOOKUP(B4,NIRF_All_Rankings!D5:W200,9,FALSE()),"—") -> 13
A51: NIRF 2025 — Medical Rank: | B51: =IFERROR(VLOOKUP(B4,NIRF_All_Rankings!D5:W200,10,FALSE()),"—") -> —
A52: NIRF 2025 — Dental Rank: | B52: =IFERROR(VLOOKUP(B4,NIRF_All_Rankings!D5:W200,11,FALSE()),"—") -> —
A53: NIRF 2025 — Law Rank: | B53: =IFERROR(VLOOKUP(B4,NIRF_All_Rankings!D5:W200,12,FALSE()),"—") -> 26
A54: NIRF 2025 — Architecture Rank: | B54: =IFERROR(VLOOKUP(B4,NIRF_All_Rankings!D5:W200,13,FALSE()),"—") -> 24
A55: NIRF 2025 — Agriculture Rank: | B55: =IFERROR(VLOOKUP(B4,NIRF_All_Rankings!D5:W200,14,FALSE()),"—") -> 17
A56: NIRF 2025 — Innovation Rank: | B56: =IFERROR(VLOOKUP(B4,NIRF_All_Rankings!D5:W200,15,FALSE()),"—") -> —
A57: NIRF 2025 — State Public Univ. Rank: | B57: =IFERROR(VLOOKUP(B4,NIRF_All_Rankings!D5:W200,16,FALSE()),"—") -> —
A58: NIRF 2025 — Open University Rank: | B58: =IFERROR(VLOOKUP(B4,NIRF_All_Rankings!D5:W200,17,FALSE()),"—") -> —
A59: NIRF 2025 — Skill University Rank: | B59: =IFERROR(VLOOKUP(B4,NIRF_All_Rankings!D5:W200,18,FALSE()),"—") -> —
A60: NIRF 2025 — SDG Rank: | B60: =IFERROR(VLOOKUP(B4,NIRF_All_Rankings!D5:W200,19,FALSE()),"—") -> —
A61: NIRF 2025 — College Rank: | B61: =IFERROR(VLOOKUP(B4,NIRF_All_Rankings!D5:W200,20,FALSE()),"—") -> —
A63: NAAC Grade: | B63: =IFERROR(INDEX(Master_Online!P:P,MATCH(B4,Master_Online!E:E,0)),"-") -> A++
A64: NAAC CGPA: | B64: =IFERROR(INDEX(Master_Online!Q:Q,MATCH(B4,Master_Online!E:E,0)),"-") -> 3.68
A65: NAAC Cycle Number: | B65: =IFERROR(INDEX(Master_Online!R:R,MATCH(B4,Master_Online!E:E,0)),"-") -> 1
A66: NAAC Declared On: | B66: =IFERROR(INDEX(Master_Online!S:S,MATCH(B4,Master_Online!E:E,0)),"-") -> 45150
...

Sheet NIRF_All_Rankings
A1: NIRF 2025 Rankings — All Categories — UGC-DEB Online Universities
A2: Source: nirfindia.org India Rankings 2025. '—' means not ranked in that category.
A4: S.No | B4: State | C4: HEI Type | D4: University Name | E4: NIRF Match Score | F4: NIRF Match Name | G4: Overall | H4: University | I4: Research | J4: Engineering | K4: Management | L4: Pharmacy | M4: Medical | N4: Dental | O4: Law | P4: Architecture | Q4: Agriculture | R4: Innovation | S4: State Public | T4: Open | U4: Skill | V4: SDG | W4: College
A5: 1 | B5: Andhra Pradesh | C5: State University | D5: Andhra University | E5: 0.58 | F5: Andhra University, Visakhapatnam | G5: 41 | H5: 23 | I5: — | J5: — | K5: — | L5: — | M5: — | N5: — | O5: — | P5: — | Q5: — | R5: — | S5: 4 | T5: — | U5: — | V5: — | W5: —
A6: 2 | B6: Andhra Pradesh | C6: Deemed-to-be University | D6: Koneru Lakshmaiah Education Foundation | E6: 0.87 | F6: Koneru Lakshmaiah Education Foundation University (K L College of Engineering) | G6: 46 | H6: 26 | I6: — | J6: 35 | K6: 70 | L6: — | M6: — | N6: — | O6: — | P6: — | Q6: — | R6: — | S6: — | T6: — | U6: — | V6: — | W6: —
A7: 3 | B7: Andhra Pradesh | C7: Deemed-to-be University | D7: Vignan's Foundation for Science, Technology and Research | E7: 1 | F7: Vignan's Foundation for Science, Technology and Research | G7: — | H7: 70 | I7: — | J7: 80 | K7: — | L7: — | M7: — | N7: — | O7: — | P7: — | Q7: — | R7: — | S7: — | T7: — | U7: — | V7: — | W7: —
A8: 4 | B8: Andhra Pradesh | C8: Private University | D8: Mohan Babu University | E8: — | F8: — | G8: — | H8: — | I8: — | J8: — | K8: — | L8: — | M8: — | N8: — | O8: — | P8: — | Q8: — | R8: — | S8: — | T8: — | U8: — | V8: — | W8: —
A9: 5 | B9: Assam | C9: Private University | D9: Assam Down Town University | E9: — | F9: — | G9: — | H9: — | I9: — | J9: — | K9: — | L9: — | M9: — | N9: — | O9: — | P9: — | Q9: — | R9: — | S9: — | T9: — | U9: — | V9: — | W9: —
A10: 6 | B10: Chhattisgarh | C10: Central University | D10: Guru Ghasidas Vishwavidyalaya | E10: 0.8 | F10: Guru Ghasidas Vishwavidyalaya | G10: — | H10: — | I10: — | J10: — | K10: — | L10: 47 | M10: — | N10: — | O10: — | P10: — | Q10: — | R10: — | S10: — | T10: — | U10: — | V10: — | W10: —
A11: 7 | B11: Chhattisgarh | C11: Private University | D11: MATS University | E11: — | F11: — | G11: — | H11: — | I11: — | J11: — | K11: — | L11: — | M11: — | N11: — | O11: — | P11: — | Q11: — | R11: — | S11: — | T11: — | U11: — | V11: — | W11: —
A12: 8 | B12: Delhi | C12: Deemed-to-be University | D12: Jamia Hamdard | E12: 1 | F12: Jamia Hamdard | G12: 74 | H12: 47 | I12: — | J12: — | K12: 87 | L12: 1 | M12: 40 | N12: — | O12: — | P12: — | Q12: — | R12: — | S12: — | T12: — | U12: — | V12: — | W12: —
A13: 9 | B13: Delhi | C13: Central University | D13: Jamia Millia Islamia University | E13: 1 | F13: Jamia Millia Islamia | G13: 13 | H13: 4 | I13: 20 | J13: 24 | K13: 28 | L13: — | M13: — | N13: 17 | O13: 8 | P13: 5 | Q13: — | R13: — | S13: — | T13: — | U13: — | V13: 3 | W13: —
A14: 10 | B14: Delhi | C14: Central University | D14: Jawaharlal Nehru University | E14: 1 | F14: Jawaharlal Nehru University | G14: 9 | H14: 2 | I14: 21 | J14: — | K14: — | L14: — | M14: — | N14: — | O14: — | P14: — | Q14: — | R14: — | S14: — | T14: — | U14: — | V14: 7 | W14: —
A15: 11 | B15: Delhi | C15: Central University | D15: Central Sanskrit University | E15: — | F15: — | G15: — | H15: — | I15: — | J15: — | K15: — | L15: — | M15: — | N15: — | O15: — | P15: — | Q15: — | R15: — | S15: — | T15: — | U15: — | V15: — | W15: —
A16: 12 | B16: Delhi | C16: State University | D16: Guru Gobind Singh Indraprastha Vishwavidyalaya | E16: 0.84 | F16: Guru Gobind Singh Indraprastha University | G16: — | H16: 93 | I16: — | J16: — | K16: 76 | L16: — | M16: — | N16: — | O16: 22 | P16: 36 | Q16: — | R16: — | S16: 22 | T16: — | U16: — | V16: — | W16: —
A17: 13 | B17: Delhi | C17: Deemed-to-be University | D17: Indian Institute of Foreign Trade | E17: 1 | F17: Indian Institute of Foreign Trade | G17: — | H17: — | I17: — | J17: — | K17: 17 | L17: — | M17: — | N17: — | O17: — | P17: — | Q17: — | R17: — | S17: — | T17: — | U17: — | V17: — | W17: —
A18: 14 | B18: Gujarat | C18: State University | D18: Gujarat University | E18: 1 | F18: Gujarat University | G18: — | H18: 74 | I18: — | J18: — | K18: — | L18: — | M18: — | N18: — | O18: — | P18: — | Q18: — | R18: — | S18: 25 | T18: — | U18: — | V18: — | W18: —
A19: 15 | B19: Gujarat | C19: Private University | D19: Charotar University of Science & Technology | E19: — | F19: — | G19: — | H19: — | I19: — | J19: — | K19: — | L19: — | M19: — | N19: — | O19: — | P19: — | Q19: — | R19: — | S19: — | T19: — | U19: — | V19: — | W19: —
A20: 16 | B20: Gujarat | C20: State Open University | D20: Dr. Babasaheb Ambedkar Open University | E20: — | F20: — | G20: — | H20: — | I20: — | J20: — | K20: — | L20: — | M20: — | N20: — | O20: — | P20: — | Q20: — | R20: — | S20: — | T20: — | U20: — | V20: — | W20: —
A21: 17 | B21: Gujarat | C21: Private University | D21: Parul University | E21: 1 | F21: Parul University | G21: — | H21: — | I21: — | J21: — | K21: — | L21: 41 | M21: — | N21: — | O21: — | P21: — | Q21: — | R21: — | S21: — | T21: — | U21: — | V21: — | W21: —
A22: 18 | B22: Gujarat | C22: Private University | D22: Marwadi University | E22: — | F22: — | G22: — | H22: — | I22: — | J22: — | K22: — | L22: — | M22: — | N22: — | O22: — | P22: — | Q22: — | R22: — | S22: — | T22: — | U22: — | V22: — | W22: —
A23: 19 | B23: Gujarat | C23: State University | D23: Gujarat Technological University | E23: 1 | F23: Gujarat Technological University | G23: — | H23: — | I23: — | J23: — | K23: — | L23: 58 | M23: — | N23: — | O23: — | P23: — | Q23: — | R23: — | S23: — | T23: — | U23: — | V23: — | W23: —
A24: 20 | B24: Gujarat | C24: Private University | D24: G.L.S. University | E24: — | F24: — | G24: — | H24: — | I24: — | J24: — | K24: — | L24: — | M24: — | N24: — | O24: — | P24: — | Q24: — | R24: — | S24: — | T24: — | U24: — | V24: — | W24: —
A25: 21 | B25: Gujarat | C25: Private University | D25: P.P. Savani University | E25: — | F25: — | G25: — | H25: — | I25: — | J25: — | K25: — | L25: — | M25: — | N25: — | O25: — | P25: — | Q25: — | R25: — | S25: — | T25: — | U25: — | V25: — | W25: —
A26: 22 | B26: Haryana | C26: State University | D26: Guru Jambheshwar University of Science and Technology | E26: 0.83 | F26: Guru Jambheshwar University of Science and Technology, Hissar | G26: — | H26: — | I26: — | J26: — | K26: — | L26: 49 | M26: — | N26: — | O26: — | P26: — | Q26: — | R26: — | S26: 32 | T26: — | U26: — | V26: — | W26: —
A27: 23 | B27: Haryana | C27: State University | D27: Kurukshetra University | E27: 1 | F27: Kurukshetra University | G27: — | H27: — | I27: — | J27: — | K27: — | L27: — | M27: — | N27: — | O27: — | P27: — | Q27: — | R27: — | S27: 35 | T27: — | U27: — | V27: — | W27: —
A28: 24 | B28: Haryana | C28: State University | D28: Maharshi Dayanand University | E28: 1 | F28: Maharshi Dayanand University | G28: — | H28: — | I28: — | J28: — | K28: — | L28: 43 | M28: — | N28: — | O28: — | P28: — | Q28: — | R28: — | S28: 46 | T28: — | U28: — | V28: — | W28: —
A29: 25 | B29: Haryana | C29: Deemed-to-be University | D29: Maharishi Markandeshwar | E29: 0.86 | F29: Maharishi Markandeshwar | G29: — | H29: 85 | I29: — | J29: — | K29: — | L29: 26 | M29: 33 | N29: — | O29: — | P29: — | Q29: — | R29: — | S29: — | T29: — | U29: — | V29: — | W29: —
A30: 26 | B30: Haryana | C30: Deemed-to-be University | D30: Manav Rachna International Institute of Research & Studies | E30: 0.99 | F30: Manav Rachna International Institute of Research & Studies | G30: — | H30: 96 | I30: — | J30: — | K30: — | L30: — | M30: — | N30: 33 | O30: — | P30: — | Q30: — | R30: — | S30: — | T30: — | U30: — | V30: — | W30: —
A31: 27 | B31: Haryana | C31: Private University | D31: Shree Guru Gobind Singh Tricentenary University | E31: 1 | F31: Shree Guru Gobind Singh Tricentenary University | G31: — | H31: — | I31: — | J31: — | K31: — | L31: 100 | M31: — | N31: — | O31: — | P31: — | Q31: — | R31: — | S31: — | T31: — | U31: — | V31: — | W31: —
A32: 28 | B32: Himachal Pradesh | C32: Private University | D32: Shoolini University of Biotechnology and Management Sciences | E32: 1 | F32: Shoolini University of Biotechnology and Management Sciences | G32: — | H32: 69 | I32: — | J32: — | K32: — | L32: 44 | M32: — | N32: — | O32: — | P32: — | Q32: — | R32: — | S32: — | T32: — | U32: — | V32: — | W32: —
A33: 29 | B33: Himachal Pradesh | C33: Central University | D33: Central University of Himachal Pradesh | E33: — | F33: — | G33: — | H33: — | I33: — | J33: — | K33: — | L33: — | M33: — | N33: — | O33: — | P33: — | Q33: — | R33: — | S33: — | T33: — | U33: — | V33: — | W33: —
A34: 30 | B34: Jammu & Kashmir | C34: State University | D34: University of Jammu | E34: 1 | F34: University of Jammu | G34: 87 | H34: 51 | I34: — | J34: — | K34: — | L34: — | M34: — | N34: — | O34: — | P34: — | Q34: — | R34: — | S34: 21 | T34: — | U34: — | V34: — | W34: —
A35: 31 | B35: Jharkhand | C35: Deemed-to-be University | D35: Birla Institute of Technology | E35: 1 | F35: Birla Institute of Technology | G35: — | H35: 92 | I35: — | J35: 51 | K35: 97 | L35: 28 | M35: — | N35: — | O35: — | P35: 22 | Q35: — | R35: — | S35: — | T35: — | U35: — | V35: — | W35: —
A36: 32 | B36: Karnataka | C36: Deemed-to-be University | D36: Jain (Deemed-to-be University) | E36: 0.55 | F36: Jain university,Bangalore | G36: — | H36: 62 | I36: — | J36: 84 | K36: 73 | L36: — | M36: — | N36: — | O36: — | P36: — | Q36: — | R36: — | S36: — | T36: — | U36: — | V36: — | W36: —
A37: 33 | B37: Karnataka | C37: Deemed-to-be University | D37: JSS Academy of Education and Research | E37: 1.02 | F37: JSS Academy of Higher Education and Research | G37: 38 | H37: 21 | I37: — | J37: — | K37: — | L37: 4 | M37: 37 | N37: 10 | O37: — | P37: — | Q37: — | R37: — | S37: — | T37: — | U37: — | V37: — | W37: —
A38: 34 | B38: Karnataka | C38: Deemed-to-be University | D38: Manipal Academy of Higher Education | E38: 1 | F38: Manipal Academy of Higher Education-Manipal | G38: 14 | H38: 3 | I38: 19 | J38: 59 | K38: 39 | L38: 8 | M38: 10 | N38: 5 | O38: — | P38: 27 | Q38: — | R38: — | S38: — | T38: — | U38: — | V38: 5 | W38: —
A39: 35 | B39: Karnataka | C39: State University | D39: Bangalore University | E39: 1 | F39: Bangalore University | G39: — | H39: 65 | I39: — | J39: — | K39: — | L39: — | M39: — | N39: — | O39: — | P39: — | Q39: — | R39: — | S39: 26 | T39: — | U39: — | V39: — | W39: —
A40: 36 | B40: Karnataka | C40: State University | D40: University of Mysore | E40: 0.82 | F40: Mysore University | G40: — | H40: 71 | I40: — | J40: — | K40: — | L40: — | M40: — | N40: — | O40: — | P40: — | Q40: — | R40: — | S40: 20 | T40: — | U40: — | V40: — | W40: —
A41: 37 | B41: Karnataka | C41: Deemed-to-be University | D41: Yenepoya | E41: — | F41: — | G41: — | H41: — | I41: — | J41: — | K41: — | L41: — | M41: — | N41: — | O41: — | P41: — | Q41: — | R41: — | S41: — | T41: — | U41: — | V41: — | W41: —
...

Sheet NIRF_Constituent_Schools
A1: NIRF rankings via constituent schools — attribution log
A2: NIRF ranks individual schools within deemed universities separately. When a school is genuinely part of a UGC-DEB umbrella university, we attribute that rank to the umbrella with a 'via [school]' note. Reading rows: the umbrella in column A; the NIRF-listed school name in column C; the rank that school holds.
A4: UGC-DEB University (umbrella) | B4: NIRF Category | C4: NIRF-Listed School | D4: Rank | E4: Score | F4: Notes
A5: Symbiosis International | B5: Management | C5: Symbiosis Institute of Business Management | D5: 11 | E5: 67.9 | F5: Constituent school of umbrella deemed university
A6: Symbiosis International | B6: Law | C6: Symbiosis Law School, Pune | D6: 7 | E6: 74.07 | F6: Constituent school of umbrella deemed university
A7: Manipal Academy of Higher Education | B7: Management | C7: T. A. Pai Management Institute Manipal | D7: 39 | E7: — | F7: Constituent school of umbrella deemed university
A8: Manipal Academy of Higher Education | B8: Engineering | C8: Manipal Institute of Technology | D8: 59 | E8: — | F8: Constituent school of umbrella deemed university
A9: Manipal Academy of Higher Education | B9: Pharmacy | C9: Manipal College of Pharmaceutical Sciences, Manipal | D9: 8 | E9: — | F9: Constituent school of umbrella deemed university
A10: Manipal Academy of Higher Education | B10: Medical | C10: Kasturba Medical College, Manipal | D10: 10 | E10: — | F10: Constituent school of umbrella deemed university
A11: Manipal Academy of Higher Education | B11: Dental | C11: Manipal College of Dental Sciences, Manipal | D11: 5 | E11: — | F11: Constituent school of umbrella deemed university
A12: Manipal Academy of Higher Education | B12: Architecture | C12: Manipal School of Architecture and Planning, MAHE | D12: 27 | E12: — | F12: Constituent school of umbrella deemed university
A13: JSS Academy of Education and Research | B13: Pharmacy | C13: JSS College of Pharmacy | D13: 4 | E13: — | F13: Constituent school of umbrella deemed university
A14: JSS Academy of Education and Research | B14: Medical | C14: JSS Medical College, Mysore | D14: 37 | E14: — | F14: Constituent school of umbrella deemed university
A15: JSS Academy of Education and Research | B15: Dental | C15: JSS Dental College and Hospital | D15: 10 | E15: — | F15: Constituent school of umbrella deemed university

Sheet Stats
A1: UGC-DEB Online Programmes — Snapshot
A3: Total programmes: | B3: =COUNTA(Master_Online!F2:F2000) -> 796
A4: Total universities: | B4: =SUMPRODUCT(1/COUNTIF(Master_Online!E2:E2000,Master_Online!E2:E2000&"")) -> 124
A6: Programmes by State | B6: Count | D6: Programmes by Category | E6: Count | G6: Programmes by UGC Notice | H6: Count | J6: AICTE Approval Breakdown | K6: Count | M6: NIRF 2025 Coverage | N6: Count | P6: NAAC Grade Distribution | Q6: Universities | S6: AACSB Coverage | T6: Universities | V6: NBA Coverage | W6: Universities
A7: Andhra Pradesh | B7: =COUNTIF(Master_Online!C:C,A7) -> 31 | D7: Acharya (PG) | E7: =COUNTIF(Master_Online!G:G,D7) -> 3 | G7: Notice 1 (Jan 2026) | H7: =COUNTIF(Master_Online!K:K,"Notice 1 (Jan 2026)") -> 750 | J7: Yes — UGC + AICTE both | K7: =COUNTIF(Master_Online!O:O,"Yes") -> 111 | M7: Universities matched to NIRF | N7: =COUNTA(NIRF_All_Rankings!E5:E200)-COUNTIF(NIRF_All_Rankings!E5:E200,"—") -> 80 | P7: A++ | Q7: =COUNTIF(University_Summary!H:H,"A++") -> 49 | S7: Has AACSB-accredited B-school | T7: =COUNTIF(University_Summary!N:N,"Accredited") -> 7 | V7: Has any NBA-accredited course | W7: =COUNTA(University_Summary!O2:O200) -> 24
A8: Assam | B8: =COUNTIF(Master_Online!C:C,A8) -> 6 | D8: B.Com | E8: =COUNTIF(Master_Online!G:G,D8) -> 71 | G8: Notice 2 (Dec 2025) | H8: =COUNTIF(Master_Online!K:K,"Notice 2 (Dec 2025)") -> 46 | J8: N/A — outside AICTE scope | K8: =COUNTIF(Master_Online!O:O,"N/A") -> 442 | M8: Ranked in Overall | N8: =COUNT(NIRF_All_Rankings!G5:G200) -> 38 | P8: A+ | Q8: =COUNTIF(University_Summary!H:H,"A+") -> 49 | S8: Has AACSB-member B-school (not accredited) | T8: =COUNTIF(University_Summary!N:N,"Member-Only") -> 0 | V8: Status: All Valid | W8: =COUNTIF(University_Summary!P:P,"All Valid") -> 9
A9: Chhattisgarh | B9: =COUNTIF(Master_Online!C:C,A9) -> 18 | D9: B.Sc | E9: =COUNTIF(Master_Online!G:G,D9) -> 2 | J9: No — UGC only, no AICTE | K9: =COUNTIF(Master_Online!O:O,"No") -> 243 | M9: Ranked in University | N9: =COUNT(NIRF_All_Rankings!H5:H200) -> 57 | P9: A | Q9: =COUNTIF(University_Summary!H:H,"A") -> 16 | S9: Total Indian schools in AACSB list | T9: 30 | V9: Status: Mixed (some expired) | W9: =COUNTIF(University_Summary!P:P,"Mixed") -> 9
A10: Delhi | B10: =COUNTIF(Master_Online!C:C,A10) -> 32 | D10: BA | E10: =COUNTIF(Master_Online!G:G,D10) -> 45 | G10: Programmes by Validity Status | H10: Count | J10: Blank (not yet processed) | K10: =COUNTBLANK(Master_Online!O2:O796) -> 0 | M10: Ranked in Research | N10: =COUNT(NIRF_All_Rankings!I5:I200) -> 13 | P10: B++ | Q10: =COUNTIF(University_Summary!H:H,"B++") -> 0 | V10: Status: All Expired | W10: =COUNTIF(University_Summary!P:P,"All Expired") -> 6
A11: Gujarat | B11: =COUNTIF(Master_Online!C:C,A11) -> 52 | D11: BBA | E11: =COUNTIF(Master_Online!G:G,D11) -> 81 | G11: Active | H11: =COUNTIF(Master_Online!N:N,G11) -> 31 | M11: Ranked in Engineering | N11: =COUNT(NIRF_All_Rankings!J5:J200) -> 25 | P11: B+ | Q11: =COUNTIF(University_Summary!H:H,"B+") -> 2 | V11: Total NBA courses (all India) | W11: 3584
A12: Haryana | B12: =COUNTIF(Master_Online!C:C,A12) -> 48 | D12: BCA | E12: =COUNTIF(Master_Online!G:G,D12) -> 59 | G12: Active (per Notice 1) | H12: =COUNTIF(Master_Online!N:N,G12) -> 750 | M12: Ranked in Management | N12: =COUNT(NIRF_All_Rankings!K5:K200) -> 26 | P12: B | Q12: =COUNTIF(University_Summary!H:H,"B") -> 0 | V12: Total NBA institutes (all India) | W12: 991
A13: Himachal Pradesh | B13: =COUNTIF(Master_Online!C:C,A13) -> 13 | D13: BLIS | E13: =COUNTIF(Master_Online!G:G,D13) -> 1 | G13: Expiring Soon | H13: =COUNTIF(Master_Online!N:N,G13) -> 0 | M13: Ranked in Pharmacy | N13: =COUNT(NIRF_All_Rankings!L5:L200) -> 26 | P13: C | Q13: =COUNTIF(University_Summary!H:H,"C") -> 0
A14: Jammu & Kashmir | B14: =COUNTIF(Master_Online!C:C,A14) -> 2 | D14: M.Com | E14: =COUNTIF(Master_Online!G:G,D14) -> 56 | G14: Expired | H14: =COUNTIF(Master_Online!N:N,G14) -> 15 | M14: Ranked in Medical | N14: =COUNT(NIRF_All_Rankings!M5:M200) -> 11 | P14: Not Accredited / Expired | Q14: =COUNTBLANK(University_Summary!H2:H124) -> 7
A15: Jharkhand | B15: =COUNTIF(Master_Online!C:C,A15) -> 6 | D15: M.Sc | E15: =COUNTIF(Master_Online!G:G,D15) -> 46 | M15: Ranked in Dental | N15: =COUNT(NIRF_All_Rankings!N5:N200) -> 13
A16: Karnataka | B16: =COUNTIF(Master_Online!C:C,A16) -> 88 | D16: MA | E16: =COUNTIF(Master_Online!G:G,D16) -> 203 | M16: Ranked in Law | N16: =COUNT(NIRF_All_Rankings!O5:O200) -> 15
A17: Kerala | B17: =COUNTIF(Master_Online!C:C,A17) -> 17 | D17: MBA | E17: =COUNTIF(Master_Online!G:G,D17) -> 133 | M17: Ranked in Architecture | N17: =COUNT(NIRF_All_Rankings!P5:P200) -> 14
A18: Madhya Pradesh | B18: =COUNTIF(Master_Online!C:C,A18) -> 12 | D18: MCA | E18: =COUNTIF(Master_Online!G:G,D18) -> 73 | M18: Ranked in Agriculture | N18: =COUNT(NIRF_All_Rankings!Q5:Q200) -> 3
A19: Maharashtra | B19: =COUNTIF(Master_Online!C:C,A19) -> 39 | D19: MLIS | E19: =COUNTIF(Master_Online!G:G,D19) -> 6 | M19: Ranked in Innovation | N19: =COUNT(NIRF_All_Rankings!R5:R200) -> 1
A20: Mizoram | B20: =COUNTIF(Master_Online!C:C,A20) -> 6 | D20: MSW | E20: =COUNTIF(Master_Online!G:G,D20) -> 5 | M20: Ranked in State Public | N20: =COUNT(NIRF_All_Rankings!S5:S200) -> 24
A21: Odisha | B21: =COUNTIF(Master_Online!C:C,A21) -> 14 | D21: PG Diploma | E21: =COUNTIF(Master_Online!G:G,D21) -> 8 | M21: Ranked in Open | N21: =COUNT(NIRF_All_Rankings!T5:T200) -> 1
A22: Punjab | B22: =COUNTIF(Master_Online!C:C,A22) -> 61 | D22: Shastri (UG) | E22: =COUNTIF(Master_Online!G:G,D22) -> 3 | M22: Ranked in Skill | N22: =COUNT(NIRF_All_Rankings!U5:U200) -> 0
A23: Rajasthan | B23: =COUNTIF(Master_Online!C:C,A23) -> 57 | M23: Ranked in SDG | N23: =COUNT(NIRF_All_Rankings!V5:V200) -> 4
A24: Sikkim | B24: =COUNTIF(Master_Online!C:C,A24) -> 15 | M24: Ranked in College | N24: =COUNT(NIRF_All_Rankings!W5:W200) -> 1
A25: Tamil Nadu | B25: =COUNTIF(Master_Online!C:C,A25) -> 128
A26: Telangana | B26: =COUNTIF(Master_Online!C:C,A26) -> 3
A27: Uttar Pradesh | B27: =COUNTIF(Master_Online!C:C,A27) -> 130
A28: Uttarakhand | B28: =COUNTIF(Master_Online!C:C,A28) -> 18
A31: Programmes by HEI Type | B31: Count
A32: Central University | B32: =COUNTIF(Master_Online!D:D,A32) -> 54
A33: Deemed-to-be University | B33: =COUNTIF(Master_Online!D:D,A33) -> 212
A34: Private University | B34: =COUNTIF(Master_Online!D:D,A34) -> 298
A35: State Open University | B35: =COUNTIF(Master_Online!D:D,A35) -> 20
A36: State University | B36: =COUNTIF(Master_Online!D:D,A36) -> 212

